<?xml version="1.0"?>
<robot xmlns:xacro="http://www.ros.org/wiki/xacro" name="barista_robot">

<xacro:property name="robot_name" value="$(arg robot_name)"/>
<xacro:property name="include_laser" value="$(arg include_laser)"/>
<xacro:arg name="include_laser" default="true"/>

<xacro:include filename="$(find barista_robot_description)/xacro/caster_wheel.xacro" />
<xacro:include filename="$(find barista_robot_description)/xacro/cup_holder_tray.xacro" />
<xacro:include filename="$(find barista_robot_description)/xacro/drive_wheel.xacro" />
<xacro:include filename="$(find barista_robot_description)/xacro/laser_scanner.xacro" />
<xacro:include filename="$(find barista_robot_description)/xacro/model_plugins.xacro" />
<xacro:include filename="$(find barista_robot_description)/xacro/rviz_materials.xacro" />
<xacro:include filename="$(find barista_robot_description)/xacro/standoff_rod.xacro" />
<xacro:include filename="$(find barista_robot_description)/xacro/barista_robot_model.gazebo.xacro" />

<xacro:drive_wheel drive_wheel_name="left_wheel"/>
<xacro:drive_wheel drive_wheel_name="right_wheel"/>

<xacro:caster_wheel caster_wheel_name="front_caster_wheel"/>
<xacro:caster_wheel caster_wheel_name="back_caster_wheel"/>

<xacro:standoff_rod standoff_rod_name="standoff_rod_1"/>
<xacro:standoff_rod standoff_rod_name="standoff_rod_2"/>
<xacro:standoff_rod standoff_rod_name="standoff_rod_3"/>
<xacro:standoff_rod standoff_rod_name="standoff_rod_4"/>

<xacro:cup_holder_tray/>
<xacro:if value="${include_laser}">
  <xacro:laser_scanner/>
  <xacro:laser_scanner_plugin/>
</xacro:if>

<xacro:state_publisher/>
<xacro:differential_drive/>

<xacro:rviz_materials/>

<xacro:gazebo_elements/>

  <!-- Base link-->
  <link name="base_link"/>

  <!-- Body link -->
  <link name="body_link">
    <visual>
      <geometry>
        <cylinder radius="0.178" length="0.155"/>
      </geometry>
      <material name="blue"/>
      <xacro:if value="${robot_name == 'rick'}">
        <material name="blue"/>
      </xacro:if>
      <xacro:if value="${robot_name == 'morty'}">
        <material name="red"/>
      </xacro:if>
    </visual>

    <collision>
      <geometry>
        <cylinder radius="0.178" length="0.155"/>
      </geometry>
    </collision>

    <inertial>
      <mass value="0.100"/>
      <inertia ixx="9.9e-04" ixy="0.0e+00" ixz="0.0e+00" iyy="9.9e-04" iyz="0.0e+00" izz="1.6e-03"/>
    </inertial>
  </link>
  
  <!-- Body joint-->
  <joint name="body_joint" type="fixed">
    <origin rpy="0 0 0" xyz="0 0 0.0951"/>
    <parent link="base_link"/>
    <child link="body_link"/>
  </joint>

  <joint name="standoff_rod_1_link_joint" type="fixed">
    <origin rpy="0 0 0" xyz="-0.030 -0.128 0.1875"/>
    <parent link="body_link"/>
    <child link="standoff_rod_1_link"/>
  </joint>

  <joint name="standoff_rod_2_joint" type="fixed">
    <origin rpy="0 0 0" xyz="-0.030 0.128 0.1875"/>
    <parent link="body_link"/>
    <child link="standoff_rod_2_link"/>
  </joint>

  <joint name="standoff_rod_3_joint" type="fixed">
    <origin rpy="0 0 0" xyz="0.030 -0.128 0.1875"/>
    <parent link="body_link"/>
    <child link="standoff_rod_3_link"/>
  </joint>

  <joint name="standoff_rod_4_joint" type="fixed">
    <origin rpy="0 0 0" xyz="0.030 0.128 0.1875"/>
    <parent link="body_link"/>
    <child link="standoff_rod_4_link"/>
  </joint>

  <!-- Wheels joint -->
  <joint name="left_wheel_joint" type="continuous">
    <origin rpy="0 1.571 1.571" xyz="0 0.140 -0.0599"/>
    <parent link="body_link"/>
    <child link="left_wheel_link"/>
    <axis rpy="0 0 0" xyz="0 0 1"/>
    <limit effort="10000" velocity="1000"/>
    <joint_properties damping="1.0" friction="1.0"/>
  </joint>
  
  <joint name="right_wheel_joint" type="continuous">
    <origin rpy="0 1.571 1.571" xyz="0 -0.140 -0.0599"/>
    <parent link="body_link"/>
    <child link="right_wheel_link"/>
    <axis rpy="0 0 0" xyz="0 0 1"/>
    <limit effort="10000" velocity="1000"/>
    <joint_properties damping="1.0" friction="1.0"/>
  </joint>

  <!-- Caster wheels joint -->
  <joint name="front_caster_wheel_yaw_joint" type="continuous">
    <origin rpy="0 0 0" xyz="0.140 0 -0.0775"/>
    <parent link="body_link"/>
    <child link="front_caster_wheel_yaw_link"/>
    <axis xyz="0 0 1"/>
    <limit effort="1000.0" velocity="100.0"/>
    <dynamics damping="0.0" friction="0.1"/>
  </joint>

  <joint name="front_caster_wheel_roll_joint" type="continuous">
    <origin rpy="0 0 0" xyz="0 0 0"/>
    <parent link="front_caster_wheel_yaw_link"/>
    <child link="front_caster_wheel_roll_link"/>
    <axis xyz="1 0 0"/>
    <limit effort="1000.0" velocity="100.0"/>
    <dynamics damping="0.0" friction="0.1"/>
  </joint>

  <joint name="front_caster_wheel_pitch_joint" type="continuous">
    <origin rpy="0 0 0" xyz="0 0 0"/>
    <parent link="front_caster_wheel_roll_link"/>
    <child link="front_caster_wheel_pitch_link"/>
    <axis xyz="0 1 0"/>
    <limit effort="1000.0" velocity="100.0"/>
    <dynamics damping="0.0" friction="0.1"/>
  </joint>

  <joint name="back_caster_wheel_yaw_joint" type="continuous">
    <origin rpy="0 0 0" xyz="-0.140 0 -0.0775"/>
    <parent link="body_link"/>
    <child link="back_caster_wheel_yaw_link"/>
    <axis xyz="0 0 1"/>
    <limit effort="1000.0" velocity="100.0"/>
    <dynamics damping="0.0" friction="0.1"/>
  </joint>

  <joint name="back_caster_wheel_roll_joint" type="continuous">
    <origin rpy="0 0 0" xyz="0 0 0"/>
    <parent link="back_caster_wheel_yaw_link"/>
    <child link="back_caster_wheel_roll_link"/>
    <axis xyz="1 0 0"/>
    <limit effort="1000.0" velocity="100.0"/>
    <dynamics damping="0.0" friction="0.1"/>
  </joint>

  <joint name="back_caster_wheel_pitch_joint" type="continuous">
    <origin rpy="0 0 0" xyz="0 0 0"/>
    <parent link="back_caster_wheel_roll_link"/>
    <child link="back_caster_wheel_pitch_link"/>
    <axis xyz="0 1 0"/>
    <limit effort="1000.0" velocity="100.0"/>
    <dynamics damping="0.0" friction="0.1"/>
  </joint>

  <!-- Cup holder tray joint-->
  <joint name="cup_holder_tray_joint" type="fixed">
    <origin rpy="0 0 0" xyz="0 0 0.3425"/>
    <parent link="body_link"/>
    <child link="cup_holder_tray_link"/>
  </joint>

  <!-- Lidar -->
  <xacro:if value="${include_laser}">
    <joint name="laser_scanner_joint" type="fixed">
      <origin rpy="0 0 0" xyz="0.100 0 0.0775"/>
      <parent link="body_link"/>
      <child link="laser_scanner_link"/>
    </joint>

    <joint name="laser_scanner_frame_joint" type="fixed">
      <origin rpy="0 0 0" xyz="0 0 0.06"/>
      <parent link="laser_scanner_link"/>
      <child link="laser_scanner_frame"/>
    </joint>
  </xacro:if>

</robot>