<?xml version="1.0"?>
<robot name="barista_robot">

  <!-- Materials -->
  <material name="white">
    <color rgba="1 1 1 1"/>
  </material>

  <material name="black">
    <color rgba="0 0 0 1"/>
  </material>
  
  <material name="dark">
    <color rgba="0.3 0.3 0.3 1"/>
  </material>
  
  <material name="grey">
    <color rgba="0.5 0.5 0.5 1"/>
  </material>
  
  <material name="red">
    <color rgba="0.8 0.0 0.0 1"/>
  </material>
  
  <material name="blue">
    <color rgba="0.0 0.0 0.8 1"/>
  </material>

  <!-- LINKS -->

  <!-- Base link -->
  <link name="base_link"/>
  
  <!-- Body link -->
  <link name="body_link">
    <visual>
      <geometry>
        <cylinder radius="0.178" length="0.155"/>
      </geometry>
      <material name="blue"/>
    </visual>

    <collision>
      <geometry>
        <cylinder radius="0.178" length="0.155"/>
      </geometry>
    </collision>

    <inertial>
      <mass value="0.100"/>
      <inertia ixx="9.9e-04" ixy="0.0e+00" ixz="0.0e+00" iyy="9.9e-04" iyz="0.0e+00" izz="1.6e-03"/>
    </inertial>
  </link>

  <gazebo reference="body_link">
    <material>Gazebo/Blue</material>
  </gazebo>

  <link name="cup_holder_tray_link">
    <visual>
      <geometry>
        <cylinder radius="0.160" length="0.090"/>
      </geometry>
      <material name="blue"/>
    </visual>

    <collision>
      <geometry>
        <cylinder radius="0.160" length="0.090"/>
      </geometry>
    </collision>

    <inertial>
      <mass value="0.050"/>
      <inertia ixx="3.5e-04" ixy="0.0e+00" ixz="0.0e+00" iyy="3.5e-04" iyz="0.0e+00" izz="6.4e-04"/>
    </inertial>
  </link>

  <gazebo reference="cup_holder_tray_link">
    <material>Gazebo/Blue</material>
  </gazebo>
  
  <!-- Standoff rod (20mm) link -->
  <link name="standoff_rod_1_link">
    <visual>
      <geometry>
        <cylinder radius="0.010" length="0.220"/>
      </geometry>
      <material name="white"/>
    </visual>

    <collision>
      <geometry>
        <cylinder radius="0.010" length="0.220"/>
      </geometry>
    </collision>

    <inertial>
      <mass value="0.020"/>
      <inertia ixx="8.1e-05" ixy="0.0e+00" ixz="0.0e+00" iyy="8.1e-05" iyz="0.0e+00" izz="1.0e-06"/>
    </inertial>
  </link>

  <gazebo reference="standoff_rod_1_link">
    <material>Gazebo/White</material>
  </gazebo>
  
  <link name="standoff_rod_2_link">
    <visual>
      <geometry>
        <cylinder radius="0.010" length="0.220"/>
      </geometry>
      <material name="white"/>
    </visual>

    <collision>
      <geometry>
        <cylinder radius="0.010" length="0.220"/>
      </geometry>
    </collision>

    <inertial>
      <mass value="0.020"/>
      <inertia ixx="8.1e-05" ixy="0.0e+00" ixz="0.0e+00" iyy="8.1e-05" iyz="0.0e+00" izz="1.0e-06"/>
    </inertial>
  </link>

  <gazebo reference="standoff_rod_2_link">
    <material>Gazebo/White</material>
  </gazebo>
  
  <link name="standoff_rod_3_link">
    <visual>
      <geometry>
        <cylinder radius="0.010" length="0.220"/>
      </geometry>
      <material name="white"/>
    </visual>

    <collision>
      <geometry>
        <cylinder radius="0.010" length="0.220"/>
      </geometry>
    </collision>

    <inertial>
      <mass value="0.020"/>
      <inertia ixx="8.1e-05" ixy="0.0e+00" ixz="0.0e+00" iyy="8.1e-05" iyz="0.0e+00" izz="1.0e-06"/>
    </inertial>
  </link>

  <gazebo reference="standoff_rod_3_link">
    <material>Gazebo/White</material>
  </gazebo>
  
  <link name="standoff_rod_4_link">
    <visual>
      <geometry>
        <cylinder radius="0.010" length="0.220"/>
      </geometry>
      <material name="white"/>
    </visual>

    <collision>
      <geometry>
        <cylinder radius="0.010" length="0.220"/>
      </geometry>
    </collision>

    <inertial>
      <mass value="0.020"/>
      <inertia ixx="8.1e-05" ixy="0.0e+00" ixz="0.0e+00" iyy="8.1e-05" iyz="0.0e+00" izz="1.0e-06"/>
    </inertial>
  </link>

  <gazebo reference="standoff_rod_4_link">
    <material>Gazebo/White</material>
  </gazebo>
  
  <!-- Drive wheels link -->
  <link name="right_wheel_link">
    <visual>
      <geometry>
        <cylinder radius="0.0352" length="0.0206"/>
      </geometry>
      <material name="black"/>
    </visual>

    <collision>
      <geometry>
        <cylinder radius="0.0352" length="0.0178"/>
      </geometry>
    </collision>

    <inertial>
      <mass value="0.025"/>
      <inertia ixx="8.6e-06" ixy="0.0e+00" ixz="0.0e+00" iyy="8.6e-06" iyz="0.0e+00" izz="1.5e-05"/>
    </inertial>
  </link>

  <gazebo reference="right_wheel_link">
    <kp>1000000000000000000000000000.0</kp>
    <kd>1000000000000000000000000000.0</kd>
    <mu1>10.0</mu1>
    <mu2>10.0</mu2>
    <material>Gazebo/Black</material>
  </gazebo>

  <link name="left_wheel_link">
    <visual>
      <geometry>
        <cylinder radius="0.0352" length="0.0206"/>
      </geometry>
      <material name="black"/>
    </visual>

    <collision>
      <geometry>
        <cylinder radius="0.0352" length="0.0206"/>
      </geometry>
    </collision>

    <inertial>
      <mass value="0.025"/>
      <inertia ixx="8.6e-06" ixy="0.0e+00" ixz="0.0e+00" iyy="8.6e-06" iyz="0.0e+00" izz="1.5e-05"/>
    </inertial>
  </link>

  <gazebo reference="left_wheel_link">
    <kp>1000000000000000000000000000.0</kp>
    <kd>1000000000000000000000000000.0</kd>
    <mu1>10.0</mu1>
    <mu2>10.0</mu2>
    <material>Gazebo/Black</material>
  </gazebo>

  <!-- Caster wheels link -->
  <link name="front_caster_wheel_yaw_link">
      <visual>
        <origin rpy="0 1.5707 1.5707" xyz="0 0 0"/>
        <geometry>          
          <cylinder length="0.001" radius="0.0045000000000000005"/>
        </geometry>
        <material name="blue"/>
      </visual>

      <collision>
        <origin rpy="0 1.5707 1.5707" xyz="0 0 0"/>
        <geometry>
          <cylinder length="0.001" radius="0.0045000000000000005"/>
        </geometry>
      </collision>

      <inertial>
          <origin rpy="0 1.5707 1.5707" xyz="0 0 0"/>
          <mass value="0.001"/>
          <inertia ixx="5.145833333333334e-09" ixy="0" ixz="0" iyy="5.145833333333334e-09" iyz="0" izz="1.0125000000000003e-08"/>
      </inertial>
  </link>

  <gazebo reference="front_caster_wheel_yaw_link">
    <material>Gazebo/Blue</material>
  </gazebo>

  <link name="front_caster_wheel_roll_link">
      <visual>
        <origin rpy="0 1.5707 1.5707" xyz="0 0 0"/>
        <geometry>
          <cylinder length="0.001" radius="0.0045000000000000005"/>
        </geometry>
        <material name="red"/>
      </visual>

      <collision>
        <origin rpy="0 1.5707 1.5707" xyz="0 0 0"/>
        <geometry>
          <cylinder length="0.001" radius="0.0045000000000000005"/>
        </geometry>
      </collision>

      <inertial>
          <origin rpy="0 1.5707 1.5707" xyz="0 0 0"/>
          <mass value="0.001"/>
          <inertia ixx="5.145833333333334e-09" ixy="0" ixz="0" iyy="5.145833333333334e-09" iyz="0" izz="1.0125000000000003e-08"/>
      </inertial>
  </link>

  <gazebo reference="front_caster_wheel_roll_link">
    <material>Gazebo/Red</material>
  </gazebo>

  <link name="front_caster_wheel_pitch_link">
    <visual>
      <origin rpy="0 1.5707 1.5707" xyz="0 0 0"/>
      <geometry>
        <sphere radius="0.0176"/>
      </geometry>
      <material name="grey"/>
    </visual>

    <collision>
      <origin rpy="0 1.5707 1.5707" xyz="0 0 0"/>
      <geometry>
        <sphere radius="0.0176"/>
      </geometry>
    </collision>

    <inertial>
        <origin rpy="0 1.5707 1.5707" xyz="0 0 0"/>
        <mass value="0.030"/>
      <inertia ixx="3.7e-06" ixy="0.0e+00" ixz="0.0e+00" iyy="3.7e-06" iyz="0.0e+00" izz="3.7e-06"/>
    </inertial>
  </link>

  <gazebo reference="front_caster_wheel_pitch_link">
    <kp>1e+27</kp>
    <kd>1e+27</kd>
    <mu1>0.5</mu1>
    <mu2>0.5</mu2>
    <material>Gazebo/Yellow</material>
  </gazebo>

  <link name="back_caster_wheel_yaw_link">
      <visual>
        <origin rpy="0 1.5707 1.5707" xyz="0 0 0"/>
        <geometry>          
          <cylinder length="0.001" radius="0.0045000000000000005"/>
        </geometry>
        <material name="blue"/>
      </visual>

      <collision>
        <origin rpy="0 1.5707 1.5707" xyz="0 0 0"/>
        <geometry>
          <cylinder length="0.001" radius="0.0045000000000000005"/>
        </geometry>
      </collision>

      <inertial>
          <origin rpy="0 1.5707 1.5707" xyz="0 0 0"/>
          <mass value="0.001"/>
          <inertia ixx="5.145833333333334e-09" ixy="0" ixz="0" iyy="5.145833333333334e-09" iyz="0" izz="1.0125000000000003e-08"/>
      </inertial>
  </link>

  <gazebo reference="back_caster_wheel_yaw_link">
    <material>Gazebo/Blue</material>
  </gazebo>

  <link name="back_caster_wheel_roll_link">
      <visual>
        <origin rpy="0 1.5707 1.5707" xyz="0 0 0"/>
        <geometry>
          <cylinder length="0.001" radius="0.0045000000000000005"/>
        </geometry>
        <material name="red"/>
      </visual>

      <collision>
        <origin rpy="0 1.5707 1.5707" xyz="0 0 0"/>
        <geometry>
          <cylinder length="0.001" radius="0.0045000000000000005"/>
        </geometry>
      </collision>

      <inertial>
          <origin rpy="0 1.5707 1.5707" xyz="0 0 0"/>
          <mass value="0.001"/>
          <inertia ixx="5.145833333333334e-09" ixy="0" ixz="0" iyy="5.145833333333334e-09" iyz="0" izz="1.0125000000000003e-08"/>
      </inertial>
  </link>

  <gazebo reference="back_caster_wheel_roll_link">
    <material>Gazebo/Red</material>
  </gazebo>

  <link name="back_caster_wheel_pitch_link">
    <visual>
      <origin rpy="0 1.5707 1.5707" xyz="0 0 0"/>
      <geometry>
        <sphere radius="0.0176"/>
      </geometry>
      <material name="grey"/>
    </visual>

    <collision>
      <origin rpy="0 1.5707 1.5707" xyz="0 0 0"/>
      <geometry>
        <sphere radius="0.0176"/>
      </geometry>
    </collision>

    <inertial>
        <origin rpy="0 1.5707 1.5707" xyz="0 0 0"/>
        <mass value="0.030"/>
      <inertia ixx="3.7e-06" ixy="0.0e+00" ixz="0.0e+00" iyy="3.7e-06" iyz="0.0e+00" izz="3.7e-06"/>
    </inertial>
  </link>

  <gazebo reference="back_caster_wheel_pitch_link">
    <kp>1e+27</kp>
    <kd>1e+27</kd>
    <mu1>0.5</mu1>
    <mu2>0.5</mu2>
    <material>Gazebo/Yellow</material>
  </gazebo>

  <!-- Lidar spinner link -->
  <link name="lidar_link">
    <visual>
      <geometry>
        <mesh filename="package://barista_robot_description/meshes/hokuyo_urg_04lx.dae" scale="1 1 1"/>
      </geometry>
      <material name="black"/>
    </visual>

    <collision>
      <geometry>
        <mesh filename="package://barista_robot_description/meshes/hokuyo_urg_04lx.dae" scale="1 1 1"/>
        <!-- <cylinder radius="0.0327" length="0.0188"/> -->
      </geometry>
    </collision>

    <inertial>
      <mass value="0.050"/>
      <inertia ixx="1.5e-05" ixy="0.0e+00" ixz="0.0e+00" iyy="1.5e-05" iyz="0.0e+00" izz="2.7e-05"/>
    </inertial>
  </link>

  <gazebo reference="lidar_link">
    <material>Gazebo/Black</material>
  </gazebo>

  <!-- JOINTS -->

  <!-- Body joint-->
  <joint name="body_joint" type="fixed">
    <origin rpy="0 0 0" xyz="0 0 0.0951"/>
    <parent link="base_link"/>
    <child link="body_link"/>
  </joint>

  <joint name="standoff_rod_1_link_joint" type="fixed">
    <origin rpy="0 0 0" xyz="-0.030 -0.128 0.1875"/>
    <parent link="body_link"/>
    <child link="standoff_rod_1_link"/>
  </joint>

  <joint name="standoff_rod_2_joint" type="fixed">
    <origin rpy="0 0 0" xyz="-0.030 0.128 0.1875"/>
    <parent link="body_link"/>
    <child link="standoff_rod_2_link"/>
  </joint>

  <joint name="standoff_rod_3_joint" type="fixed">
    <origin rpy="0 0 0" xyz="0.030 -0.128 0.1875"/>
    <parent link="body_link"/>
    <child link="standoff_rod_3_link"/>
  </joint>

  <joint name="standoff_rod_4_joint" type="fixed">
    <origin rpy="0 0 0" xyz="0.030 0.128 0.1875"/>
    <parent link="body_link"/>
    <child link="standoff_rod_4_link"/>
  </joint>

  <!-- Wheels joint -->
  <joint name="left_wheel_joint" type="continuous">
    <origin rpy="0 1.571 1.571" xyz="0 0.158 -0.0599"/>
    <parent link="body_link"/>
    <child link="left_wheel_link"/>
    <axis rpy="0 0 0" xyz="0 0 1"/>
    <limit effort="10000" velocity="1000"/>
    <joint_properties damping="1.0" friction="1.0"/>
  </joint>
  
  <joint name="right_wheel_joint" type="continuous">
    <origin rpy="0 1.571 1.571" xyz="0 -0.158 -0.0599"/>
    <parent link="body_link"/>
    <child link="right_wheel_link"/>
    <axis rpy="0 0 0" xyz="0 0 1"/>
    <limit effort="10000" velocity="1000"/>
    <joint_properties damping="1.0" friction="1.0"/>
  </joint>

  <!-- Caster wheels joint -->
  <joint name="front_caster_wheel_yaw_joint" type="continuous">
    <origin rpy="0 0 0" xyz="0.158 0 -0.0775"/>
    <parent link="body_link"/>
    <child link="front_caster_wheel_yaw_link"/>
    <axis xyz="0 0 1"/>
    <limit effort="1000.0" velocity="100.0"/>
    <dynamics damping="0.0" friction="0.1"/>
  </joint>

  <joint name="front_caster_wheel_roll_joint" type="continuous">
    <origin rpy="0 0 0" xyz="0 0 0"/>
    <parent link="front_caster_wheel_yaw_link"/>
    <child link="front_caster_wheel_roll_link"/>
    <axis xyz="1 0 0"/>
    <limit effort="1000.0" velocity="100.0"/>
    <dynamics damping="0.0" friction="0.1"/>
  </joint>

  <joint name="front_caster_wheel_pitch_joint" type="continuous">
    <origin rpy="0 0 0" xyz="0 0 0"/>
    <parent link="front_caster_wheel_roll_link"/>
    <child link="front_caster_wheel_pitch_link"/>
    <axis xyz="0 1 0"/>
    <limit effort="1000.0" velocity="100.0"/>
    <dynamics damping="0.0" friction="0.1"/>
  </joint>

  <joint name="back_caster_wheel_yaw_joint" type="continuous">
    <origin rpy="0 0 0" xyz="-0.158 0 -0.0775"/>
    <parent link="body_link"/>
    <child link="back_caster_wheel_yaw_link"/>
    <axis xyz="0 0 1"/>
    <limit effort="1000.0" velocity="100.0"/>
    <dynamics damping="0.0" friction="0.1"/>
  </joint>

  <joint name="back_caster_wheel_roll_joint" type="continuous">
    <origin rpy="0 0 0" xyz="0 0 0"/>
    <parent link="back_caster_wheel_yaw_link"/>
    <child link="back_caster_wheel_roll_link"/>
    <axis xyz="1 0 0"/>
    <limit effort="1000.0" velocity="100.0"/>
    <dynamics damping="0.0" friction="0.1"/>
  </joint>

  <joint name="back_caster_wheel_pitch_joint" type="continuous">
    <origin rpy="0 0 0" xyz="0 0 0"/>
    <parent link="back_caster_wheel_roll_link"/>
    <child link="back_caster_wheel_pitch_link"/>
    <axis xyz="0 1 0"/>
    <limit effort="1000.0" velocity="100.0"/>
    <dynamics damping="0.0" friction="0.1"/>
  </joint>

  <!-- Cup holder tray joint-->
  <joint name="cup_holder_tray_joint" type="fixed">
    <origin rpy="0 0 0" xyz="0 0 0.3425"/>
    <parent link="body_link"/>
    <child link="cup_holder_tray_link"/>
  </joint>

  <!-- Lidar -->
  <joint name="lidar_joint" type="fixed">
    <origin rpy="0 0 0" xyz="0.100 0 0.0775"/>
    <parent link="body_link"/>
    <child link="lidar_link"/>
  </joint>

  <!-- PLUGINS -->

  <!-- Joint state publisher -->
  <gazebo>
    <plugin name="barista_robot_joint_state" filename="libgazebo_ros_joint_state_publisher.so">
      <ros>
          <remapping>~/out:=joint_states</remapping>
      </ros>
      <update_rate>30.0</update_rate>
      <joint_name>left_wheel_joint</joint_name>
      <joint_name>right_wheel_joint</joint_name>
      <joint_name>front_caster_wheel_yaw_joint</joint_name>
      <joint_name>front_caster_wheel_roll_joint</joint_name>
      <joint_name>front_caster_wheel_pitch_joint</joint_name>
      <joint_name>back_caster_wheel_yaw_joint</joint_name>
      <joint_name>back_caster_wheel_roll_joint</joint_name>
      <joint_name>back_caster_wheel_pitch_joint</joint_name>
    </plugin>
  </gazebo>

<!-- Differential drive -->
  <gazebo>
    <plugin filename="libgazebo_ros_diff_drive.so" name="differential_drive_controller">

      <!-- wheels -->
      <left_joint>left_wheel_joint</left_joint>
      <right_joint>right_wheel_joint</right_joint>

      <!-- kinematics -->
      <wheel_separation>0.316</wheel_separation>
      <wheel_diameter>0.0704</wheel_diameter>

      <!-- limits -->
      <max_wheel_torque>1.0</max_wheel_torque>
      <max_wheel_acceleration>2.0</max_wheel_acceleration>

      <!-- output -->
      <publish_odom>true</publish_odom>
      <publish_odom_tf>true</publish_odom_tf>

      <odometry_frame>odom</odometry_frame>
      <robot_base_frame>base_link</robot_base_frame>

    </plugin>
  </gazebo>

  <!-- SENSORS -->
  <gazebo reference="lidar_link">
    <sensor name="sensor_ray" type="ray">
        <pose>0 0 0 0 0 0</pose>
        <ray>
          <scan>
            <horizontal>
              <samples>200</samples>
              <resolution>1.0</resolution>
              <min_angle>-3.14</min_angle>
              <max_angle>3.14</max_angle>
            </horizontal>
          </scan>
          <range>
            <min>0.1</min>
            <max>5.0</max>
          </range>
        </ray>
        <always_on>true</always_on>
        <visualize>true</visualize>
        <update_rate>100.0</update_rate>
        <plugin name="laser" filename="libgazebo_ros_ray_sensor.so">
          <ros>
            <namespace>/barista_robot</namespace>
            <remapping>~/out:=scan</remapping>
          </ros>
          <output_type>sensor_msgs/LaserScan</output_type>
        </plugin>
      </sensor>
	</gazebo>

</robot>